<?xml version="1.0"?>
<robot name="mrm" xmlns:xacro="http://www.ros.org/wiki/xacro">
  <link name="base_link">
    <visual>
	    <origin rpy="0 0 0" xyz="0.0 0 0" />
      <geometry>
        <cylinder length="0.5" radius="0.1"/>
      </geometry>
    </visual>
    <inertial>
	    <origin rpy="0 0 0" xyz="0.0 0 0" />
        <mass value="3"/>
         <inertia ixx="0.002"  ixy="0"  ixz="0.0" iyy= "0.002" iyz="0" izz="0.0005" />
      </inertial>
     <collision>
	    <origin rpy="0 0 0" xyz="0.0 0 0" />
        <geometry>
            <cylinder length="0.5" radius="0.1"/>
        </geometry>
     </collision>
  </link>
  
	<joint name="base_link_to_link_01" type="revolute">
	  <axis xyz="1 0 0"/>
		<limit effort="10.0" lower="-1.57" upper="1.57" velocity="0.5"/>
		<origin rpy="3.14 0 0" xyz="0.0 0 0.25"/>
		<parent link="base_link"/>
		<child link="link_01"/>
	</joint>

  <link name="link_01">
    <visual>
	    <origin rpy="0 0 0" xyz="0.0 0 -0.25" />
      <geometry>
        <cylinder length="0.5" radius="0.08"/>
      </geometry>
    </visual>
    <inertial>
	    <origin rpy="0 0 0" xyz="0.0 0 0" />
        <mass value="0.01"/>
         <inertia ixx="0.00224"  ixy="0"  ixz="0.0" iyy= "0.00224" iyz="0" izz="0.00032" />
      </inertial>
     <collision>
	    <origin rpy="0 0 0" xyz="0.0 0 0" />
        <geometry>
        <cylinder length="0.5" radius="0.08"/>
        </geometry>
     </collision>
  </link>

 <joint name="link_01_to_link_02" type="revolute">
	  <axis xyz="1 0 0"/>
		<limit effort="10.0" lower="-1.57" upper="1.57" velocity="0.5"/>
		<origin rpy="3.14 0 0" xyz="0.0 0 -0.5"/>
		<parent link="link_01"/>
		<child link="link_02"/>
	</joint>


  <link name="link_02">
    <visual>
	    <origin rpy="0 0 0" xyz="0 0 0.25" />
      <geometry>
        <cylinder length="0.5" radius="0.06"/>
      </geometry>
    </visual>
    <inertial>
	    <origin rpy="0 0 0" xyz="0.0 0 0" />
        <mass value="0.01"/>
         <inertia ixx="0.00217"  ixy="0.0"  ixz="0.0" iyy= "0.00217" iyz="0" izz="0.00018" />
      </inertial>
     <collision>
	    <origin rpy="0 0 0" xyz="0.0 0 0" />
        <geometry>
        <cylinder length="0.5" radius="0.06"/>
        </geometry>
     </collision>
  </link>

  <gazebo>
    <plugin name="gazebo_ros_control" filename="libgazebo_ros_control.so">
      <robotNamespace>/threelink</robotNamespace>
    </plugin>
  </gazebo>

  <gazebo reference="base_link_to_link_01">
        <kp>1000.0</kp>
        <kd>1000.0</kd>
        <mu1>10.0</mu1>
        <mu2>10.0</mu2>
        <material>Gazebo/Red</material>
    </gazebo>

  <transmission name="tran1">
    <type>transmission_interface/SimpleTransmission</type>
    <joint name="base_link_to_link_01">
      <hardwareInterface>hardware_interface/EffortJointInterface</hardwareInterface>
    </joint>
    <actuator name="motor1">
      <hardwareInterface>EffortJointInterface</hardwareInterface>
      <mechanicalReduction>1</mechanicalReduction>
    </actuator>
  </transmission>


  <gazebo reference="link_01_to_link_02">
        <kp>1000.0</kp>
        <kd>1000.0</kd>
        <mu1>10.0</mu1>
        <mu2>10.0</mu2>
        <material>Gazebo/Red</material>
    </gazebo>

  <transmission name="tran2">
    <type>transmission_interface/SimpleTransmission</type>
    <joint name="link_01_to_link_02">
      <hardwareInterface>hardware_interface/EffortJointInterface</hardwareInterface>
    </joint>
    <actuator name="motor2">
      <hardwareInterface>EffortJointInterface</hardwareInterface>
      <mechanicalReduction>1</mechanicalReduction>
    </actuator>
  </transmission> -->
  
</robot>
